<mujoco model="go2">
  <compiler angle="radian" meshdir="assets" autolimits="true"/>

  <option cone="elliptic" impratio="100"/>

  <default>
    <default class="go2">
      <geom friction="0.6" margin="0.001" condim="1"/>
      <joint axis="0 1 0" damping="1" armature="0.01" frictionloss="0.2"/>
      <motor ctrlrange="-23.7 23.7"/>
      <default class="abduction">
        <joint axis="1 0 0" range="-1.0472 1.0472"/>
      </default>
      <default class="hip">
        <default class="front_hip">
          <joint range="-1.5708 3.4907"/>
        </default>
        <default class="back_hip">
          <joint range="-0.5236 4.5379"/>
        </default>
      </default>
      <default class="knee">
        <joint range="-2.7227 -0.83776"/>
        <motor ctrlrange="-45.43 45.43"/>
      </default>
      <default class="visual">
        <geom type="mesh" contype="0" conaffinity="0" group="2"/>
      </default>
      <default class="collision">
        <geom group="3"/>
        <default class="foot">
          <geom size="0.022" pos="-0.002 0 -0.213" priority="1" solimp="0.015 1 0.031"  condim="4" 
            friction="0.8 0.02 0.01"/> <!-- solimp="0.015 1 0.031"--> <!-- solimp="0.915 1 0.031"-->
        </default>
      </default>
    </default>
  </default>

  <asset>
    <material name="metal" rgba=".9 .95 .95 1"/>
    <material name="black" rgba="0 0 0 1"/>
    <material name="white" rgba="1 1 1 1"/>
    <material name="gray" rgba="0.671705 0.692426 0.774270 1"/>

    <mesh file="base_0.obj"/>
    <mesh file="base_1.obj"/>
    <mesh file="base_2.obj"/>
    <mesh file="base_3.obj"/>
    <mesh file="base_4.obj"/>
    <mesh file="hip_0.obj"/>
    <mesh file="hip_1.obj"/>
    <mesh file="thigh_0.obj"/>
    <mesh file="thigh_1.obj"/>
    <mesh file="thigh_mirror_0.obj"/>
    <mesh file="thigh_mirror_1.obj"/>
    <mesh file="calf_0.obj"/>
    <mesh file="calf_1.obj"/>
    <mesh file="calf_mirror_0.obj"/>
    <mesh file="calf_mirror_1.obj"/>
    <mesh file="foot.obj"/>
  </asset>

  <worldbody>
    <body name="base" pos="0 0 0.445" childclass="go2">
      <inertial pos="0.021112 0 -0.005366" quat="-0.000543471 0.713435 -0.00173769 0.700719" mass="6.921"
        diaginertia="0.107027 0.0980771 0.0244531"/>
      <freejoint/>
      <geom mesh="base_0" material="black" class="visual"/>
      <geom mesh="base_1" material="black" class="visual"/>
      <geom mesh="base_2" material="black" class="visual"/>
      <geom mesh="base_3" material="white" class="visual"/>
      <geom mesh="base_4" material="gray" class="visual"/>
      <geom size="0.1881 0.04675 0.057" type="box" class="collision"/>
      <geom size="0.05 0.045" pos="0.285 0 0.01" type="cylinder" class="collision"/>
      <geom size="0.047" pos="0.293 0 -0.06" class="collision"/>
      <site name="imu" pos="-0.02557 0 0.04232"/>

      <body name="FR_hip" pos="0.1934 -0.0465 0">
        <inertial pos="-0.0054 -0.00194 -0.000105" quat="0.498237 0.505462 0.499245 0.497014" mass="0.678"
          diaginertia="0.00088403 0.000596003 0.000479967"/>
        <joint name="FR_hip_joint" class="abduction"/>
        <geom mesh="hip_0" material="metal" class="visual" quat="4.63268e-05 1 0 0"/>
        <geom mesh="hip_1" material="gray" class="visual" quat="4.63268e-05 1 0 0"/>
        <geom size="0.046 0.02" pos="0 -0.08 0" quat="0.707107 0.707107 0 0" type="cylinder" class="collision"/>
        <body name="FR_thigh" pos="0 -0.0955 0">
          <inertial pos="-0.00374 0.0223 -0.0327" quat="0.551623 -0.0200632 0.0847635 0.829533" mass="1.152"
            diaginertia="0.00594973 0.00584149 0.000878787"/>
          <joint name="FR_thigh_joint" class="front_hip"/>
          <geom mesh="thigh_mirror_0" material="metal" class="visual"/>
          <geom mesh="thigh_mirror_1" material="gray" class="visual"/>
          <geom size="0.1065 0.01225 0.017" pos="0 0 -0.1065" quat="0.707107 0 0.707107 0" type="box" class="collision"/>
          <body name="FR_calf" pos="0 0 -0.213">
            <inertial pos="0.00629595 0.000622121 -0.141417" quat="0.703508 -0.00450087 0.00154099 0.710672"
              mass="0.241352" diaginertia="0.0014901 0.00146356 5.31397e-05"/>
            <joint name="FR_calf_joint" class="knee"/>
            <geom mesh="calf_mirror_0" material="gray" class="visual"/>
            <geom mesh="calf_mirror_1" material="black" class="visual"/>
            <geom size="0.013 0.06" pos="0.01 0 -0.06" quat="0.995004 0 -0.0998334 0" type="cylinder" class="collision"/>
            <geom size="0.011 0.0325" pos="0.02 0 -0.148" quat="0.999688 0 0.0249974 0" type="cylinder" class="collision"/>
            <geom pos="0 0 -0.213" mesh="foot" class="visual" material="black"/>
            <geom name="FR" class="foot"/>
            <site name="FR" pos="0 0 -0.213" type="sphere" size="0.023" group="3" />

          </body>
        </body>
      </body>



      <body name="FL_hip" pos="0.1934 0.0465 0">
        <inertial pos="-0.0054 0.00194 -0.000105" quat="0.497014 0.499245 0.505462 0.498237" mass="0.678"
          diaginertia="0.00088403 0.000596003 0.000479967"/>
        <joint name="FL_hip_joint" class="abduction"/>
        <geom mesh="hip_0" material="metal" class="visual"/>
        <geom mesh="hip_1" material="gray" class="visual"/>
        <geom size="0.046 0.02" pos="0 0.08 0" quat="1 1 0 0" type="cylinder" class="collision"/>
        <body name="FL_thigh" pos="0 0.0955 0">
          <inertial pos="-0.00374 -0.0223 -0.0327" quat="0.829533 0.0847635 -0.0200632 0.551623" mass="1.152"
            diaginertia="0.00594973 0.00584149 0.000878787"/>
          <joint name="FL_thigh_joint" class="front_hip"/>
          <geom mesh="thigh_0" material="metal" class="visual"/>
          <geom mesh="thigh_1" material="gray" class="visual"/>
          <geom size="0.1065 0.01225 0.017" pos="0 0 -0.1065" quat="0.707107 0 0.707107 0" type="box" class="collision"/>
          <body name="FL_calf" pos="0 0 -0.213">
            <inertial pos="0.00629595 -0.000622121 -0.141417" quat="0.710672 0.00154099 -0.00450087 0.703508"
              mass="0.241352" diaginertia="0.0014901 0.00146356 5.31397e-05"/>
            <joint name="FL_calf_joint" class="knee"/>
            <geom mesh="calf_0" material="gray" class="visual"/>
            <geom mesh="calf_1" material="black" class="visual"/>
            <geom size="0.012 0.06" pos="0.008 0 -0.06" quat="0.994493 0 -0.104807 0" type="cylinder" class="collision"/>
            <geom size="0.011 0.0325" pos="0.02 0 -0.148" quat="0.999688 0 0.0249974 0" type="cylinder" class="collision"/>
            <geom pos="0 0 -0.213" mesh="foot" class="visual" material="black"/>
            <geom name="FL" class="foot"/>
            <site name="FL" pos="0 0 -0.213" type="sphere" size="0.023" group="3"/>

          </body>
        </body>
      </body>


      <body name="RR_hip" pos="-0.1934 -0.0465 0">
        <inertial pos="0.0054 -0.00194 -0.000105" quat="0.499245 0.497014 0.498237 0.505462" mass="0.678"
          diaginertia="0.00088403 0.000596003 0.000479967"/>
        <joint name="RR_hip_joint" class="abduction"/>
        <geom mesh="hip_0" material="metal" class="visual" quat="2.14617e-09 4.63268e-05 4.63268e-05 -1"/>
        <geom mesh="hip_1" material="gray" class="visual" quat="2.14617e-09 4.63268e-05 4.63268e-05 -1"/>
        <geom size="0.046 0.02" pos="0 -0.08 0" quat="0.707107 0.707107 0 0" type="cylinder" class="collision"/>
        <body name="RR_thigh" pos="0 -0.0955 0">
          <inertial pos="-0.00374 0.0223 -0.0327" quat="0.551623 -0.0200632 0.0847635 0.829533" mass="1.152"
            diaginertia="0.00594973 0.00584149 0.000878787"/>
          <joint name="RR_thigh_joint" class="back_hip"/>
          <geom mesh="thigh_mirror_0" material="metal" class="visual"/>
          <geom mesh="thigh_mirror_1" material="gray" class="visual"/>
          <geom size="0.1065 0.01225 0.017" pos="0 0 -0.1065" quat="0.707107 0 0.707107 0" type="box" class="collision"/>
          <body name="RR_calf" pos="0 0 -0.213">
            <inertial pos="0.00629595 0.000622121 -0.141417" quat="0.703508 -0.00450087 0.00154099 0.710672"
              mass="0.241352" diaginertia="0.0014901 0.00146356 5.31397e-05"/>
            <joint name="RR_calf_joint" class="knee"/>
            <geom mesh="calf_mirror_0" material="gray" class="visual"/>
            <geom mesh="calf_mirror_1" material="black" class="visual"/>
            <geom size="0.013 0.06" pos="0.01 0 -0.06" quat="0.995004 0 -0.0998334 0" type="cylinder" class="collision"/>
            <geom size="0.011 0.0325" pos="0.02 0 -0.148" quat="0.999688 0 0.0249974 0" type="cylinder" class="collision"/>
            <geom pos="0 0 -0.213" mesh="foot" class="visual" material="black"/>
            <geom name="RR" class="foot"/>
            <site name="RR" pos="0 0 -0.213" type="sphere" size="0.023" group="3"/>

          </body>
        </body>
      </body>

      <body name="RL_hip" pos="-0.1934 0.0465 0">
        <inertial pos="0.0054 0.00194 -0.000105" quat="0.505462 0.498237 0.497014 0.499245" mass="0.678"
          diaginertia="0.00088403 0.000596003 0.000479967"/>
        <joint name="RL_hip_joint" class="abduction"/>
        <geom mesh="hip_0" material="metal" class="visual" quat="4.63268e-05 0 1 0"/>
        <geom mesh="hip_1" material="gray" class="visual" quat="4.63268e-05 0 1 0"/>
        <geom size="0.046 0.02" pos="0 0.08 0" quat="0.707107 0.707107 0 0" type="cylinder" class="collision"/>
        <body name="RL_thigh" pos="0 0.0955 0">
          <inertial pos="-0.00374 -0.0223 -0.0327" quat="0.829533 0.0847635 -0.0200632 0.551623" mass="1.152"
            diaginertia="0.00594973 0.00584149 0.000878787"/>
          <joint name="RL_thigh_joint" class="back_hip"/>
          <geom mesh="thigh_0" material="metal" class="visual"/>
          <geom mesh="thigh_1" material="gray" class="visual"/>
          <geom size="0.1065 0.01225 0.017" pos="0 0 -0.1065" quat="0.707107 0 0.707107 0" type="box" class="collision"/>
          <body name="RL_calf" pos="0 0 -0.213">
            <inertial pos="0.00629595 -0.000622121 -0.141417" quat="0.710672 0.00154099 -0.00450087 0.703508"
              mass="0.241352" diaginertia="0.0014901 0.00146356 5.31397e-05"/>
            <joint name="RL_calf_joint" class="knee"/>
            <geom mesh="calf_0" material="gray" class="visual"/>
            <geom mesh="calf_1" material="black" class="visual"/>
            <geom size="0.013 0.06" pos="0.01 0 -0.06" quat="0.995004 0 -0.0998334 0" type="cylinder" class="collision"/>
            <geom size="0.011 0.0325" pos="0.02 0 -0.148" quat="0.999688 0 0.0249974 0" type="cylinder" class="collision"/>
            <geom pos="0 0 -0.213" mesh="foot" class="visual" material="black"/>
            <geom name="RL" class="foot"/>
            <site name="RL" pos="0 0 -0.213" type="sphere" size="0.023" group="3"/>

          </body>
        </body>
      </body>

    </body>






  </worldbody>


  <actuator>
    <motor class="abduction" gear="1" name="FR_hip" joint="FR_hip_joint"/>
    <motor class="hip"       gear="1" name="FR_thigh" joint="FR_thigh_joint"/>
    <motor class="knee"      gear="1" name="FR_calf" joint="FR_calf_joint"/>
    <motor class="abduction" gear="1" name="FL_hip" joint="FL_hip_joint"/>
    <motor class="hip"       gear="1" name="FL_thigh" joint="FL_thigh_joint"/>
    <motor class="knee"      gear="1" name="FL_calf" joint="FL_calf_joint"/>
    <motor class="abduction" gear="1" name="RR_hip" joint="RR_hip_joint"/>
    <motor class="hip"       gear="1" name="RR_thigh" joint="RR_thigh_joint"/>
    <motor class="knee"      gear="1" name="RR_calf" joint="RR_calf_joint"/>
    <motor class="abduction" gear="1" name="RL_hip" joint="RL_hip_joint"/>
    <motor class="hip"       gear="1" name="RL_thigh" joint="RL_thigh_joint"/>
    <motor class="knee"      gear="1" name="RL_calf" joint="RL_calf_joint"/>

    <position class="abduction" name="pservo_FR_hip" joint="FR_hip_joint" kp="0.0"    />
    <velocity class="abduction" name="vservo_FR_hip" joint="FR_hip_joint" kv="5.5"  />
    <position class="hip" name="pservo_FR_thigh" joint="FR_thigh_joint"   kp="0.0"    />
    <velocity class="hip" name="vservo_FR_thigh" joint="FR_thigh_joint"   kv="3.0"  />
    <position class="knee" name="pservo_FR_calf" joint="FR_calf_joint"    kp="0.0"    />
    <velocity class="knee" name="vservo_FR_calf" joint="FR_calf_joint"    kv="2.0"  />

    <position class="abduction" name="pservo_FL_hip" joint="FL_hip_joint" kp="0.0"    />
    <velocity class="abduction" name="vservo_FL_hip" joint="FL_hip_joint" kv="5.5"  />
    <position class="hip" name="pservo_FL_thigh" joint="FL_thigh_joint"   kp="0.0"    />
    <velocity class="hip" name="vservo_FL_thigh" joint="FL_thigh_joint"   kv="3.0"  />
    <position class="knee" name="pservo_FL_calf" joint="FL_calf_joint"    kp="0.0"    />
    <velocity class="knee" name="vservo_FL_calf" joint="FL_calf_joint"    kv="2.0"  />

    <position class="abduction" name="pservo_RR_hip" joint="RR_hip_joint" kp="0.0"    />
    <velocity class="abduction" name="vservo_RR_hip" joint="RR_hip_joint" kv="5.5"  />
    <position class="hip" name="pservo_RR_thigh" joint="RR_thigh_joint"   kp="0.0"    />
    <velocity class="hip" name="vservo_RR_thigh" joint="RR_thigh_joint"   kv="3.0"  />
    <position class="knee" name="pservo_RR_calf" joint="RR_calf_joint"    kp="0.0"    />
    <velocity class="knee" name="vservo_RR_calf" joint="RR_calf_joint"    kv="2.0"  />

    <position class="abduction" name="pservo_RL_hip" joint="RL_hip_joint" kp="0.0"    />
    <velocity class="abduction" name="vservo_RL_hip" joint="RL_hip_joint" kv="5.5"  />
    <position class="hip" name="pservo_RL_thigh" joint="RL_thigh_joint"   kp="0.0"    />
    <velocity class="hip" name="vservo_RL_thigh" joint="RL_thigh_joint"   kv="3.0"  />
    <position class="knee" name="pservo_RL_calf" joint="RL_calf_joint"    kp="0.0"    />
    <velocity class="knee" name="vservo_RL_calf" joint="RL_calf_joint"    kv="2.0"  />


  </actuator>


    <sensor>

        <jointpos name="FR_hip_pos"     joint="FR_hip_joint"/>
        <jointpos name="FR_thigh_pos"   joint="FR_thigh_joint"/>
        <jointpos name="FR_calf_pos"    joint="FR_calf_joint"/>
        <jointpos name="FL_hip_pos"     joint="FL_hip_joint"/>
        <jointpos name="FL_thigh_pos"   joint="FL_thigh_joint"/>
        <jointpos name="FL_calf_pos"    joint="FL_calf_joint"/>
        <jointpos name="RR_hip_pos"     joint="RR_hip_joint"/>
        <jointpos name="RR_thigh_pos"   joint="RR_thigh_joint"/>
        <jointpos name="RR_calf_pos"    joint="RR_calf_joint" />
        <jointpos name="RL_hip_pos"     joint="RL_hip_joint"/>
        <jointpos name="RL_thigh_pos"   joint="RL_thigh_joint"/>
        <jointpos name="RL_calf_pos"    joint="RL_calf_joint"/>

        <jointvel name="FR_hip_vel"     joint="FR_hip_joint"/>
        <jointvel name="FR_thigh_vel"   joint="FR_thigh_joint"/>
        <jointvel name="FR_calf_vel"    joint="FR_calf_joint"/>
        <jointvel name="FL_hip_vel"     joint="FL_hip_joint"/>
        <jointvel name="FL_thigh_vel"   joint="FL_thigh_joint"/>
        <jointvel name="FL_calf_vel"    joint="FL_calf_joint"/>
        <jointvel name="RR_hip_vel"     joint="RR_hip_joint"/>
        <jointvel name="RR_thigh_vel"   joint="RR_thigh_joint"/>
        <jointvel name="RR_calf_vel"    joint="RR_calf_joint" />
        <jointvel name="RL_hip_vel"     joint="RL_hip_joint"/>
        <jointvel name="RL_thigh_vel"   joint="RL_thigh_joint"/>
        <jointvel name="RL_calf_vel"    joint="RL_calf_joint"/>

        <!-- Body IMU/PosQuat  -->
        <accelerometer name="Body_Acc" site="imu"/>
        <gyro name="Body_Gyro" site="imu"/>

        <framepos name="Body_Pos" objtype="site" objname="imu"/>
        <framequat name="Body_Quat" objtype="site" objname="imu"/>
        
        <!-- Extra sensors for tips Pos/Quat -->
        <framepos name="FR_Pos" objtype="site" objname="FR" reftype="site" refname="imu"/>
        <framequat name="FR_Quat" objtype="site" objname="FR"  reftype="site" refname="imu"/>

        <framepos name="FL_Pos" objtype="site" objname="FL"  reftype="site" refname="imu"/>
        <framequat name="FL_Quat" objtype="site" objname="FL"  reftype="site" refname="imu"/>

        <framepos name="RR_Pos" objtype="site" objname="RR"  reftype="site" refname="imu"/>
        <framequat name="RR_Quat" objtype="site" objname="RR"  reftype="site" refname="imu"/>

        <framepos name="RL_Pos" objtype="site" objname="RL"  reftype="site" refname="imu"/>
        <framequat name="RL_Quat" objtype="site" objname="RL"  reftype="site" refname="imu"/>

        <!-- Extra IMU sensor on foot tips -->
        <accelerometer name="FR_Acc" site="FR"/>
        <gyro name="FR_Gyro" site="FR"/>

        <accelerometer name="FL_Acc" site="FL"/>
        <gyro name="FL_Gyro" site="FL"/>

        <accelerometer name="RR_Acc" site="RR"/>
        <gyro name="RR_Gyro" site="RR"/>

        <accelerometer name="RL_Acc" site="RL"/>
        <gyro name="RL_Gyro" site="RL"/>       


        <!-- Force sensors -->
        <force name="FR_foot_force" site="FR"/> 
        <force name="FL_foot_force" site="FL"/> 
        <force name="RR_foot_force" site="RR"/> 
        <force name="RL_foot_force" site="RL"/> 

        <!-- Velocity of the CoM -->
        <velocimeter name="Body_Vel" site="imu"/>

    </sensor>


    <contact >
      
        <pair  geom1="FR" geom2="slippery_surface" condim="4" friction="0.0 0.0 0.0" /> 
        <pair  geom1="FL" geom2="slippery_surface" condim="4" friction="0.0 0.0 0.0" />
        <pair  geom1="RR" geom2="slippery_surface" condim="4" friction="0.0 0.0 0.0" />
        <pair  geom1="RL" geom2="slippery_surface" condim="4" friction="0.0 0.0 0.0" />

<!-- 0.3 0.2 0.25
0.15 0.1 0.12
0.08 0.05 0.07
0.02 0.01 0.03 -->
        <pair  geom1="FR" geom2="normal_surface" condim="4" friction="0.8 0.2 0.2" /> 
        <pair  geom1="FL" geom2="normal_surface" condim="4" friction="0.8 0.2 0.2" />
        <pair  geom1="RR" geom2="normal_surface" condim="4" friction="0.8 0.2 0.2" />
        <pair  geom1="RL" geom2="normal_surface" condim="4" friction="0.8 0.2 0.2" />


    </contact> 

</mujoco>
